I'm sorry, but an uncaught exception occurred.

While running game code:
ScriptError: Name (u'game/tl/russian/Cakegame.rpy', 1579430867, 54095) is defined twice, at game/tl/belarusian/Cakegame.rpy:4 and tl/russian/Cakegame.rpyc:4.

-- Full Traceback ------------------------------------------------------------

Full traceback:
  File "/Users/uyakauleu/development/games/moe-era/renpy/bootstrap.py", line 316, in bootstrap
    renpy.main.main()
  File "/Users/uyakauleu/development/games/moe-era/renpy/main.py", line 422, in main
    renpy.game.script.load_script()  # sets renpy.game.script.
  File "/Users/uyakauleu/development/games/moe-era/renpy/script.py", line 275, in load_script
    self.load_appropriate_file(".rpyc", ".rpy", dir, fn, initcode)
  File "/Users/uyakauleu/development/games/moe-era/renpy/script.py", line 779, in load_appropriate_file
    self.finish_load(stmts, initcode, filename=lastfn)
  File "/Users/uyakauleu/development/games/moe-era/renpy/script.py", line 456, in finish_load
    check_name(node)
  File "/Users/uyakauleu/development/games/moe-era/renpy/script.py", line 439, in check_name
    bad_node.filename, bad_node.linenumber))
ScriptError: Name (u'game/tl/russian/Cakegame.rpy', 1579430867, 54095) is defined twice, at game/tl/belarusian/Cakegame.rpy:4 and tl/russian/Cakegame.rpyc:4.

Darwin-22.1.0-x86_64-i386-64bit
Ren'Py 7.3.5.606
 
Mon Jan  9 21:37:12 2023
